Created log @ 2023-10-27 21:19:29.512133
################
In Pycraft. Error: None @ 2023-10-27 21:19:29.512133
Traceback (most recent call last):
  File "D:\Documents\GitHub\PycraftReimagined\src\programs\game_engine.py", line 168, in __init__
    self.clouds_prog["render_fog"] = Registry.render_fog
  File "C:\Users\pamj0\AppData\Local\Programs\Python\Python310\lib\site-packages\moderngl\__init__.py", line 501, in __setitem__
    self._members[key].value = value
KeyError: 'render_fog'
################
################
In Pycraft. Error: None @ 2023-10-27 21:21:33.708794
Traceback (most recent call last):
  File "D:\Documents\GitHub\PycraftReimagined\src\programs\game_engine.py", line 105, in __init__
    self.clouds_prog) = shader_utils.load_programs().load_program_files()
  File "D:\Documents\GitHub\PycraftReimagined\src\programs\utility\shader_utils.py", line 45, in load_program_files
    clouds_prog = moderngl_window.WindowConfig.load_program(
  File "C:\Users\pamj0\AppData\Local\Programs\Python\Python310\lib\site-packages\moderngl_window\context\base\window.py", line 1381, in load_program
    return resources.programs.load(
  File "C:\Users\pamj0\AppData\Local\Programs\Python\Python310\lib\site-packages\moderngl_window\resources\programs.py", line 33, in load
    return super().load(meta)
  File "C:\Users\pamj0\AppData\Local\Programs\Python\Python310\lib\site-packages\moderngl_window\resources\base.py", line 52, in load
    return meta.loader_cls(meta).load()
  File "C:\Users\pamj0\AppData\Local\Programs\Python\Python310\lib\site-packages\moderngl_window\loaders\program\single.py", line 59, in load
    prog = shaders.create()
  File "C:\Users\pamj0\AppData\Local\Programs\Python\Python310\lib\site-packages\moderngl_window\opengl\program.py", line 169, in create
    program = self.ctx.program(
  File "C:\Users\pamj0\AppData\Local\Programs\Python\Python310\lib\site-packages\moderngl\__init__.py", line 2092, in program
    res.mglo, res._members, res._subroutines, res._geom, res._glo = self.mglo.program(
_moderngl.Error: GLSL Compiler failed

vertex_shader
=============
0(20) : error C1067: too little data in type constructor


################
################
In Pycraft. Error: None @ 2023-10-27 21:32:6.369772
Traceback (most recent call last):
  File "D:\Documents\GitHub\PycraftReimagined\src\programs\game_engine.py", line 107, in __init__
    self.clouds_prog) = shader_utils.load_programs().load_program_files()
  File "D:\Documents\GitHub\PycraftReimagined\src\programs\utility\shader_utils.py", line 45, in load_program_files
    clouds_prog = moderngl_window.WindowConfig.load_program(
  File "C:\Users\pamj0\AppData\Local\Programs\Python\Python310\lib\site-packages\moderngl_window\context\base\window.py", line 1381, in load_program
    return resources.programs.load(
  File "C:\Users\pamj0\AppData\Local\Programs\Python\Python310\lib\site-packages\moderngl_window\resources\programs.py", line 33, in load
    return super().load(meta)
  File "C:\Users\pamj0\AppData\Local\Programs\Python\Python310\lib\site-packages\moderngl_window\resources\base.py", line 52, in load
    return meta.loader_cls(meta).load()
  File "C:\Users\pamj0\AppData\Local\Programs\Python\Python310\lib\site-packages\moderngl_window\loaders\program\single.py", line 59, in load
    prog = shaders.create()
  File "C:\Users\pamj0\AppData\Local\Programs\Python\Python310\lib\site-packages\moderngl_window\opengl\program.py", line 169, in create
    program = self.ctx.program(
  File "C:\Users\pamj0\AppData\Local\Programs\Python\Python310\lib\site-packages\moderngl\__init__.py", line 2092, in program
    res.mglo, res._members, res._subroutines, res._geom, res._glo = self.mglo.program(
_moderngl.Error: GLSL Compiler failed

vertex_shader
=============
0(61) : error C7608: OpenGL does not allow using 'discard or demote' in this profile
0(64) : error C1503: undefined variable "render_fog"
0(76) : error C0000: syntax error, unexpected identifier, expecting ',' or ';' at token "gl_Position"


################
################
In Pycraft. Error: None @ 2023-10-27 21:32:35.118058
Traceback (most recent call last):
  File "D:\Documents\GitHub\PycraftReimagined\src\programs\game_engine.py", line 107, in __init__
    self.clouds_prog) = shader_utils.load_programs().load_program_files()
  File "D:\Documents\GitHub\PycraftReimagined\src\programs\utility\shader_utils.py", line 45, in load_program_files
    clouds_prog = moderngl_window.WindowConfig.load_program(
  File "C:\Users\pamj0\AppData\Local\Programs\Python\Python310\lib\site-packages\moderngl_window\context\base\window.py", line 1381, in load_program
    return resources.programs.load(
  File "C:\Users\pamj0\AppData\Local\Programs\Python\Python310\lib\site-packages\moderngl_window\resources\programs.py", line 33, in load
    return super().load(meta)
  File "C:\Users\pamj0\AppData\Local\Programs\Python\Python310\lib\site-packages\moderngl_window\resources\base.py", line 52, in load
    return meta.loader_cls(meta).load()
  File "C:\Users\pamj0\AppData\Local\Programs\Python\Python310\lib\site-packages\moderngl_window\loaders\program\single.py", line 59, in load
    prog = shaders.create()
  File "C:\Users\pamj0\AppData\Local\Programs\Python\Python310\lib\site-packages\moderngl_window\opengl\program.py", line 169, in create
    program = self.ctx.program(
  File "C:\Users\pamj0\AppData\Local\Programs\Python\Python310\lib\site-packages\moderngl\__init__.py", line 2092, in program
    res.mglo, res._members, res._subroutines, res._geom, res._glo = self.mglo.program(
_moderngl.Error: GLSL Compiler failed

vertex_shader
=============
0(64) : error C0000: syntax error, unexpected identifier, expecting ',' or ';' at token "gl_Position"


################
################
In Pycraft. Error: None @ 2023-10-27 21:45:25.779656
Traceback (most recent call last):
  File "D:\Documents\GitHub\PycraftReimagined\src\programs\game_engine.py", line 408, in render_game_engine
    self.clouds_prog["cloud_scale"] = cloud_scale
  File "C:\Users\pamj0\AppData\Local\Programs\Python\Python310\lib\site-packages\moderngl\__init__.py", line 501, in __setitem__
    self._members[key].value = value
KeyError: 'cloud_scale'
################
################
In Pycraft. Error: None @ 2023-10-27 21:53:22.625565
Traceback (most recent call last):
  File "D:\Documents\GitHub\PycraftReimagined\src\programs\game_engine.py", line 107, in __init__
    self.objects_shadow["map"] = self.vao.instance(self.depth_prog)
AttributeError: 'create_game_engine' object has no attribute 'objects_shadow'
################
################
In Pycraft. Error: None @ 2023-10-29 10:23:34.54014
Traceback (most recent call last):
  File "D:\Documents\GitHub\PycraftReimagined\src\programs\game_engine.py", line 103, in __init__
    self.clouds_prog) = shader_utils.load_programs().load_program_files()
  File "D:\Documents\GitHub\PycraftReimagined\src\programs\utility\shader_utils.py", line 40, in load_program_files
    skysphere_prog = moderngl_window.WindowConfig.load_program(
  File "C:\Users\pamj0\AppData\Local\Programs\Python\Python310\lib\site-packages\moderngl_window\context\base\window.py", line 1381, in load_program
    return resources.programs.load(
  File "C:\Users\pamj0\AppData\Local\Programs\Python\Python310\lib\site-packages\moderngl_window\resources\programs.py", line 33, in load
    return super().load(meta)
  File "C:\Users\pamj0\AppData\Local\Programs\Python\Python310\lib\site-packages\moderngl_window\resources\base.py", line 52, in load
    return meta.loader_cls(meta).load()
  File "C:\Users\pamj0\AppData\Local\Programs\Python\Python310\lib\site-packages\moderngl_window\loaders\program\single.py", line 59, in load
    prog = shaders.create()
  File "C:\Users\pamj0\AppData\Local\Programs\Python\Python310\lib\site-packages\moderngl_window\opengl\program.py", line 169, in create
    program = self.ctx.program(
  File "C:\Users\pamj0\AppData\Local\Programs\Python\Python310\lib\site-packages\moderngl\__init__.py", line 2092, in program
    res.mglo, res._members, res._subroutines, res._geom, res._glo = self.mglo.program(
_moderngl.Error: GLSL Compiler failed

fragment_shader
===============
0(101) : error C1503: undefined variable "uv0"
0(108) : error C0000: syntax error, unexpected identifier, expecting ',' or ';' at token "fragColor"


################
################
In Pycraft. Error: None @ 2023-10-29 10:23:50.895895
Traceback (most recent call last):
  File "D:\Documents\GitHub\PycraftReimagined\src\programs\game_engine.py", line 103, in __init__
    self.clouds_prog) = shader_utils.load_programs().load_program_files()
  File "D:\Documents\GitHub\PycraftReimagined\src\programs\utility\shader_utils.py", line 40, in load_program_files
    skysphere_prog = moderngl_window.WindowConfig.load_program(
  File "C:\Users\pamj0\AppData\Local\Programs\Python\Python310\lib\site-packages\moderngl_window\context\base\window.py", line 1381, in load_program
    return resources.programs.load(
  File "C:\Users\pamj0\AppData\Local\Programs\Python\Python310\lib\site-packages\moderngl_window\resources\programs.py", line 33, in load
    return super().load(meta)
  File "C:\Users\pamj0\AppData\Local\Programs\Python\Python310\lib\site-packages\moderngl_window\resources\base.py", line 52, in load
    return meta.loader_cls(meta).load()
  File "C:\Users\pamj0\AppData\Local\Programs\Python\Python310\lib\site-packages\moderngl_window\loaders\program\single.py", line 59, in load
    prog = shaders.create()
  File "C:\Users\pamj0\AppData\Local\Programs\Python\Python310\lib\site-packages\moderngl_window\opengl\program.py", line 169, in create
    program = self.ctx.program(
  File "C:\Users\pamj0\AppData\Local\Programs\Python\Python310\lib\site-packages\moderngl\__init__.py", line 2092, in program
    res.mglo, res._members, res._subroutines, res._geom, res._glo = self.mglo.program(
_moderngl.Error: GLSL Compiler failed

fragment_shader
===============
0(101) : error C1503: undefined variable "uv0"
0(108) : error C0000: syntax error, unexpected identifier, expecting ',' or ';' at token "fragColor"


################
################
In Pycraft. Error: None @ 2023-10-29 10:24:16.408923
Traceback (most recent call last):
  File "D:\Documents\GitHub\PycraftReimagined\src\programs\game_engine.py", line 103, in __init__
    self.clouds_prog) = shader_utils.load_programs().load_program_files()
  File "D:\Documents\GitHub\PycraftReimagined\src\programs\utility\shader_utils.py", line 40, in load_program_files
    skysphere_prog = moderngl_window.WindowConfig.load_program(
  File "C:\Users\pamj0\AppData\Local\Programs\Python\Python310\lib\site-packages\moderngl_window\context\base\window.py", line 1381, in load_program
    return resources.programs.load(
  File "C:\Users\pamj0\AppData\Local\Programs\Python\Python310\lib\site-packages\moderngl_window\resources\programs.py", line 33, in load
    return super().load(meta)
  File "C:\Users\pamj0\AppData\Local\Programs\Python\Python310\lib\site-packages\moderngl_window\resources\base.py", line 52, in load
    return meta.loader_cls(meta).load()
  File "C:\Users\pamj0\AppData\Local\Programs\Python\Python310\lib\site-packages\moderngl_window\loaders\program\single.py", line 59, in load
    prog = shaders.create()
  File "C:\Users\pamj0\AppData\Local\Programs\Python\Python310\lib\site-packages\moderngl_window\opengl\program.py", line 169, in create
    program = self.ctx.program(
  File "C:\Users\pamj0\AppData\Local\Programs\Python\Python310\lib\site-packages\moderngl\__init__.py", line 2092, in program
    res.mglo, res._members, res._subroutines, res._geom, res._glo = self.mglo.program(
_moderngl.Error: GLSL Compiler failed

fragment_shader
===============
0(108) : error C0000: syntax error, unexpected identifier, expecting ',' or ';' at token "fragColor"


################
################
In Pycraft. Error: None @ 2023-10-29 10:24:46.875336
Traceback (most recent call last):
  File "D:\Documents\GitHub\PycraftReimagined\src\programs\game_engine.py", line 103, in __init__
    self.clouds_prog) = shader_utils.load_programs().load_program_files()
  File "D:\Documents\GitHub\PycraftReimagined\src\programs\utility\shader_utils.py", line 40, in load_program_files
    skysphere_prog = moderngl_window.WindowConfig.load_program(
  File "C:\Users\pamj0\AppData\Local\Programs\Python\Python310\lib\site-packages\moderngl_window\context\base\window.py", line 1381, in load_program
    return resources.programs.load(
  File "C:\Users\pamj0\AppData\Local\Programs\Python\Python310\lib\site-packages\moderngl_window\resources\programs.py", line 33, in load
    return super().load(meta)
  File "C:\Users\pamj0\AppData\Local\Programs\Python\Python310\lib\site-packages\moderngl_window\resources\base.py", line 52, in load
    return meta.loader_cls(meta).load()
  File "C:\Users\pamj0\AppData\Local\Programs\Python\Python310\lib\site-packages\moderngl_window\loaders\program\single.py", line 59, in load
    prog = shaders.create()
  File "C:\Users\pamj0\AppData\Local\Programs\Python\Python310\lib\site-packages\moderngl_window\opengl\program.py", line 169, in create
    program = self.ctx.program(
  File "C:\Users\pamj0\AppData\Local\Programs\Python\Python310\lib\site-packages\moderngl\__init__.py", line 2092, in program
    res.mglo, res._members, res._subroutines, res._geom, res._glo = self.mglo.program(
_moderngl.Error: GLSL Compiler failed

fragment_shader
===============
0(108) : error C1503: undefined variable "cloud_col"


################
################
In Pycraft. Error: None @ 2023-10-29 10:25:9.755686
Traceback (most recent call last):
  File "D:\Documents\GitHub\PycraftReimagined\src\programs\game_engine.py", line 103, in __init__
    self.clouds_prog) = shader_utils.load_programs().load_program_files()
  File "D:\Documents\GitHub\PycraftReimagined\src\programs\utility\shader_utils.py", line 40, in load_program_files
    skysphere_prog = moderngl_window.WindowConfig.load_program(
  File "C:\Users\pamj0\AppData\Local\Programs\Python\Python310\lib\site-packages\moderngl_window\context\base\window.py", line 1381, in load_program
    return resources.programs.load(
  File "C:\Users\pamj0\AppData\Local\Programs\Python\Python310\lib\site-packages\moderngl_window\resources\programs.py", line 33, in load
    return super().load(meta)
  File "C:\Users\pamj0\AppData\Local\Programs\Python\Python310\lib\site-packages\moderngl_window\resources\base.py", line 52, in load
    return meta.loader_cls(meta).load()
  File "C:\Users\pamj0\AppData\Local\Programs\Python\Python310\lib\site-packages\moderngl_window\loaders\program\single.py", line 59, in load
    prog = shaders.create()
  File "C:\Users\pamj0\AppData\Local\Programs\Python\Python310\lib\site-packages\moderngl_window\opengl\program.py", line 169, in create
    program = self.ctx.program(
  File "C:\Users\pamj0\AppData\Local\Programs\Python\Python310\lib\site-packages\moderngl\__init__.py", line 2092, in program
    res.mglo, res._members, res._subroutines, res._geom, res._glo = self.mglo.program(
_moderngl.Error: GLSL Compiler failed

fragment_shader
===============
0(107) : error C1503: undefined variable "cloud_col"


################
################
In Pycraft. Error: None @ 2023-10-29 10:25:26.740137
Traceback (most recent call last):
  File "D:\Documents\GitHub\PycraftReimagined\src\programs\game_engine.py", line 103, in __init__
    self.clouds_prog) = shader_utils.load_programs().load_program_files()
  File "D:\Documents\GitHub\PycraftReimagined\src\programs\utility\shader_utils.py", line 40, in load_program_files
    skysphere_prog = moderngl_window.WindowConfig.load_program(
  File "C:\Users\pamj0\AppData\Local\Programs\Python\Python310\lib\site-packages\moderngl_window\context\base\window.py", line 1381, in load_program
    return resources.programs.load(
  File "C:\Users\pamj0\AppData\Local\Programs\Python\Python310\lib\site-packages\moderngl_window\resources\programs.py", line 33, in load
    return super().load(meta)
  File "C:\Users\pamj0\AppData\Local\Programs\Python\Python310\lib\site-packages\moderngl_window\resources\base.py", line 52, in load
    return meta.loader_cls(meta).load()
  File "C:\Users\pamj0\AppData\Local\Programs\Python\Python310\lib\site-packages\moderngl_window\loaders\program\single.py", line 59, in load
    prog = shaders.create()
  File "C:\Users\pamj0\AppData\Local\Programs\Python\Python310\lib\site-packages\moderngl_window\opengl\program.py", line 169, in create
    program = self.ctx.program(
  File "C:\Users\pamj0\AppData\Local\Programs\Python\Python310\lib\site-packages\moderngl\__init__.py", line 2092, in program
    res.mglo, res._members, res._subroutines, res._geom, res._glo = self.mglo.program(
_moderngl.Error: GLSL Compiler failed

fragment_shader
===============
(0) : error C0000: syntax error, unexpected $end at token "<EOF>"


################
################
In Pycraft. Error: None @ 2023-10-29 10:25:43.530686
Traceback (most recent call last):
  File "D:\Documents\GitHub\PycraftReimagined\src\programs\game_engine.py", line 103, in __init__
    self.clouds_prog) = shader_utils.load_programs().load_program_files()
  File "D:\Documents\GitHub\PycraftReimagined\src\programs\utility\shader_utils.py", line 45, in load_program_files
    clouds_prog = moderngl_window.WindowConfig.load_program(
  File "C:\Users\pamj0\AppData\Local\Programs\Python\Python310\lib\site-packages\moderngl_window\context\base\window.py", line 1381, in load_program
    return resources.programs.load(
  File "C:\Users\pamj0\AppData\Local\Programs\Python\Python310\lib\site-packages\moderngl_window\resources\programs.py", line 33, in load
    return super().load(meta)
  File "C:\Users\pamj0\AppData\Local\Programs\Python\Python310\lib\site-packages\moderngl_window\resources\base.py", line 52, in load
    return meta.loader_cls(meta).load()
  File "C:\Users\pamj0\AppData\Local\Programs\Python\Python310\lib\site-packages\moderngl_window\loaders\program\single.py", line 59, in load
    prog = shaders.create()
  File "C:\Users\pamj0\AppData\Local\Programs\Python\Python310\lib\site-packages\moderngl_window\opengl\program.py", line 169, in create
    program = self.ctx.program(
  File "C:\Users\pamj0\AppData\Local\Programs\Python\Python310\lib\site-packages\moderngl\__init__.py", line 2092, in program
    res.mglo, res._members, res._subroutines, res._geom, res._glo = self.mglo.program(
_moderngl.Error: GLSL Compiler failed

fragment_shader
===============
0(96) : error C1503: undefined variable "uv"


################
################
In Pycraft. Error: None @ 2023-10-29 10:26:49.408956
Traceback (most recent call last):
  File "D:\Documents\GitHub\PycraftReimagined\src\programs\game_engine.py", line 103, in __init__
    self.clouds_prog) = shader_utils.load_programs().load_program_files()
  File "D:\Documents\GitHub\PycraftReimagined\src\programs\utility\shader_utils.py", line 45, in load_program_files
    clouds_prog = moderngl_window.WindowConfig.load_program(
  File "C:\Users\pamj0\AppData\Local\Programs\Python\Python310\lib\site-packages\moderngl_window\context\base\window.py", line 1381, in load_program
    return resources.programs.load(
  File "C:\Users\pamj0\AppData\Local\Programs\Python\Python310\lib\site-packages\moderngl_window\resources\programs.py", line 33, in load
    return super().load(meta)
  File "C:\Users\pamj0\AppData\Local\Programs\Python\Python310\lib\site-packages\moderngl_window\resources\base.py", line 52, in load
    return meta.loader_cls(meta).load()
  File "C:\Users\pamj0\AppData\Local\Programs\Python\Python310\lib\site-packages\moderngl_window\loaders\program\single.py", line 59, in load
    prog = shaders.create()
  File "C:\Users\pamj0\AppData\Local\Programs\Python\Python310\lib\site-packages\moderngl_window\opengl\program.py", line 169, in create
    program = self.ctx.program(
  File "C:\Users\pamj0\AppData\Local\Programs\Python\Python310\lib\site-packages\moderngl\__init__.py", line 2092, in program
    res.mglo, res._members, res._subroutines, res._geom, res._glo = self.mglo.program(
_moderngl.Error: GLSL Compiler failed

fragment_shader
===============
0(96) : error C1503: undefined variable "uv"


################
################
In Pycraft. Error: None @ 2023-10-29 10:28:10.867672
Traceback (most recent call last):
  File "D:\Documents\GitHub\PycraftReimagined\src\programs\game_engine.py", line 164, in __init__
    self.sky_sphere_prog["render_fog"] = Registry.render_fog
  File "C:\Users\pamj0\AppData\Local\Programs\Python\Python310\lib\site-packages\moderngl\__init__.py", line 501, in __setitem__
    self._members[key].value = value
KeyError: 'render_fog'
################
################
In Pycraft. Error: None @ 2023-10-29 10:28:52.443923
Traceback (most recent call last):
  File "D:\Documents\GitHub\PycraftReimagined\src\programs\game_engine.py", line 164, in __init__
    self.sky_sphere_prog["render_fog"] = Registry.render_fog
  File "C:\Users\pamj0\AppData\Local\Programs\Python\Python310\lib\site-packages\moderngl\__init__.py", line 501, in __setitem__
    self._members[key].value = value
KeyError: 'render_fog'
################
################
In Pycraft. Error: None @ 2023-10-29 10:29:17.790576
Traceback (most recent call last):
  File "D:\Documents\GitHub\PycraftReimagined\src\programs\game_engine.py", line 203, in __init__
    self.clouds_prog["w_max"].value = Registry.render_distance
AttributeError: 'create_game_engine' object has no attribute 'clouds_prog'
################
################
In Pycraft. Error: None @ 2023-10-29 10:33:50.2132
Traceback (most recent call last):
  File "D:\Documents\GitHub\PycraftReimagined\src\programs\game_engine.py", line 102, in __init__
    self.sky_sphere_prog) = shader_utils.load_programs().load_program_files()
  File "D:\Documents\GitHub\PycraftReimagined\src\programs\utility\shader_utils.py", line 40, in load_program_files
    skysphere_prog = moderngl_window.WindowConfig.load_program(
  File "C:\Users\pamj0\AppData\Local\Programs\Python\Python310\lib\site-packages\moderngl_window\context\base\window.py", line 1381, in load_program
    return resources.programs.load(
  File "C:\Users\pamj0\AppData\Local\Programs\Python\Python310\lib\site-packages\moderngl_window\resources\programs.py", line 33, in load
    return super().load(meta)
  File "C:\Users\pamj0\AppData\Local\Programs\Python\Python310\lib\site-packages\moderngl_window\resources\base.py", line 52, in load
    return meta.loader_cls(meta).load()
  File "C:\Users\pamj0\AppData\Local\Programs\Python\Python310\lib\site-packages\moderngl_window\loaders\program\single.py", line 59, in load
    prog = shaders.create()
  File "C:\Users\pamj0\AppData\Local\Programs\Python\Python310\lib\site-packages\moderngl_window\opengl\program.py", line 169, in create
    program = self.ctx.program(
  File "C:\Users\pamj0\AppData\Local\Programs\Python\Python310\lib\site-packages\moderngl\__init__.py", line 2092, in program
    res.mglo, res._members, res._subroutines, res._geom, res._glo = self.mglo.program(
_moderngl.Error: GLSL Compiler failed

fragment_shader
===============
0(97) : error C1105: cannot call a non-function


################
################
In Pycraft. Error: None @ 2023-10-29 10:36:18.693716
Traceback (most recent call last):
  File "D:\Documents\GitHub\PycraftReimagined\src\programs\game_engine.py", line 107, in __init__
    self.sky_sphere_prog["texture0"].value = 0
  File "C:\Users\pamj0\AppData\Local\Programs\Python\Python310\lib\site-packages\moderngl\__init__.py", line 498, in __getitem__
    return self._members[key]
KeyError: 'texture0'
################
################
In Pycraft. Error: None @ 2023-10-29 10:37:1.926024
Traceback (most recent call last):
  File "D:\Documents\GitHub\PycraftReimagined\src\programs\game_engine.py", line 107, in __init__
    self.sky_sphere_prog["texture0"].value = 0
  File "C:\Users\pamj0\AppData\Local\Programs\Python\Python310\lib\site-packages\moderngl\__init__.py", line 498, in __getitem__
    return self._members[key]
KeyError: 'texture0'
################
################
In Pycraft. Error: None @ 2023-10-29 10:38:41.81519
Traceback (most recent call last):
  File "D:\Documents\GitHub\PycraftReimagined\src\programs\game_engine.py", line 102, in __init__
    self.sky_sphere_prog) = shader_utils.load_programs().load_program_files()
  File "D:\Documents\GitHub\PycraftReimagined\src\programs\utility\shader_utils.py", line 40, in load_program_files
    skysphere_prog = moderngl_window.WindowConfig.load_program(
  File "C:\Users\pamj0\AppData\Local\Programs\Python\Python310\lib\site-packages\moderngl_window\context\base\window.py", line 1381, in load_program
    return resources.programs.load(
  File "C:\Users\pamj0\AppData\Local\Programs\Python\Python310\lib\site-packages\moderngl_window\resources\programs.py", line 33, in load
    return super().load(meta)
  File "C:\Users\pamj0\AppData\Local\Programs\Python\Python310\lib\site-packages\moderngl_window\resources\base.py", line 52, in load
    return meta.loader_cls(meta).load()
  File "C:\Users\pamj0\AppData\Local\Programs\Python\Python310\lib\site-packages\moderngl_window\loaders\program\single.py", line 59, in load
    prog = shaders.create()
  File "C:\Users\pamj0\AppData\Local\Programs\Python\Python310\lib\site-packages\moderngl_window\opengl\program.py", line 169, in create
    program = self.ctx.program(
  File "C:\Users\pamj0\AppData\Local\Programs\Python\Python310\lib\site-packages\moderngl\__init__.py", line 2092, in program
    res.mglo, res._members, res._subroutines, res._geom, res._glo = self.mglo.program(
_moderngl.Error: GLSL Compiler failed

vertex_shader
=============
0(14) : error C0000: syntax error, unexpected ';', expecting '{' at token ";"
0(20) : error C1503: undefined variable "alpha_height"
0(21) : error C0000: syntax error, unexpected '}', expecting ',' or ';' at token "}"


################
################
In Pycraft. Error: None @ 2023-10-29 10:38:58.11734
Traceback (most recent call last):
  File "D:\Documents\GitHub\PycraftReimagined\src\programs\game_engine.py", line 102, in __init__
    self.sky_sphere_prog) = shader_utils.load_programs().load_program_files()
  File "D:\Documents\GitHub\PycraftReimagined\src\programs\utility\shader_utils.py", line 40, in load_program_files
    skysphere_prog = moderngl_window.WindowConfig.load_program(
  File "C:\Users\pamj0\AppData\Local\Programs\Python\Python310\lib\site-packages\moderngl_window\context\base\window.py", line 1381, in load_program
    return resources.programs.load(
  File "C:\Users\pamj0\AppData\Local\Programs\Python\Python310\lib\site-packages\moderngl_window\resources\programs.py", line 33, in load
    return super().load(meta)
  File "C:\Users\pamj0\AppData\Local\Programs\Python\Python310\lib\site-packages\moderngl_window\resources\base.py", line 52, in load
    return meta.loader_cls(meta).load()
  File "C:\Users\pamj0\AppData\Local\Programs\Python\Python310\lib\site-packages\moderngl_window\loaders\program\single.py", line 59, in load
    prog = shaders.create()
  File "C:\Users\pamj0\AppData\Local\Programs\Python\Python310\lib\site-packages\moderngl_window\opengl\program.py", line 169, in create
    program = self.ctx.program(
  File "C:\Users\pamj0\AppData\Local\Programs\Python\Python310\lib\site-packages\moderngl\__init__.py", line 2092, in program
    res.mglo, res._members, res._subroutines, res._geom, res._glo = self.mglo.program(
_moderngl.Error: GLSL Compiler failed

vertex_shader
=============
0(14) : error C0000: syntax error, unexpected ';', expecting '{' at token ";"
0(20) : error C1503: undefined variable "alpha_height"


################
################
In Pycraft. Error: None @ 2023-10-29 10:46:33.779645
Traceback (most recent call last):
  File "D:\Documents\GitHub\PycraftReimagined\src\programs\game_engine.py", line 244, in render_game_engine
    self.DefaultSkyCol,
AttributeError: 'create_game_engine' object has no attribute 'DefaultSkyCol'
################
################
In Pycraft. Error: None @ 2023-10-29 10:51:23.846245
Traceback (most recent call last):
  File "D:\Documents\GitHub\PycraftReimagined\src\programs\game_engine.py", line 254, in render_game_engine
    Registry.camera.rot_state(-mouse_motion)
TypeError: bad operand type for unary -: 'tuple'
################
################
In Pycraft. Error: None @ 2023-10-29 10:52:28.526491
Traceback (most recent call last):
  File "D:\Documents\GitHub\PycraftReimagined\src\programs\game_engine.py", line 254, in render_game_engine
    Registry.camera.rot_state([ -x for x in mouse_motion])
TypeError: KeyboardCamera.rot_state() missing 1 required positional argument: 'dy'
################
################
In Pycraft. Error: None @ 2023-10-29 11:24:39.579731
Traceback (most recent call last):
  File "D:\Documents\GitHub\PycraftReimagined\src\programs\pycraft_main.py", line 77, in __init__
    Registry.main_menu.main()
  File "D:\Documents\GitHub\PycraftReimagined\src\programs\main_menu.py", line 52, in main
    (_, run) = Registry.events.handle()
  File "D:\Documents\GitHub\PycraftReimagined\src\programs\utility\event_utils.py", line 79, in handle
    if event.key == Registry.input_configuration["keyboard"]["pause music"]:
KeyError: 'pause music'
################
################
In Pycraft. Error: None @ 2023-11-1 21:5:5.368575
Traceback (most recent call last):
  File "D:\Documents\GitHub\PycraftReimagined\src\programs\game_engine.py", line 131, in __init__
    self.moon_prog["color"].value = (1.0, 1.0, 1.0, 1.0)
  File "C:\Users\pamj0\AppData\Local\Programs\Python\Python310\lib\site-packages\moderngl\__init__.py", line 498, in __getitem__
    return self._members[key]
KeyError: 'color'
################
################
In Pycraft. Error: None @ 2023-11-2 15:37:35.237577
Traceback (most recent call last):
  File "D:\Documents\GitHub\PycraftReimagined\src\programs\game_engine.py", line 245, in render_game_engine
    self.cloud_offset[0] += math_utils.generate_perlin_noise(
  File "C:\Users\pamj0\AppData\Local\Programs\Python\Python310\lib\site-packages\numba\core\dispatcher.py", line 468, in _compile_for_args
    error_rewrite(e, 'typing')
  File "C:\Users\pamj0\AppData\Local\Programs\Python\Python310\lib\site-packages\numba\core\dispatcher.py", line 409, in error_rewrite
    raise e.with_traceback(None)
numba.core.errors.TypingError: Failed in nopython mode pipeline (step: nopython frontend)
[1mUntyped global name 'extrapolate2':[0m [1m[1mCannot determine Numba type of <class 'functools._lru_cache_wrapper'>[0m
[1m
File "src\programs\utility\math_utils.py", line 104:[0m
[1m    def generate_perlin_noise(x, y, perm):
        <source elided>
            attn1 *= attn1
[1m            value += attn1 * attn1 * extrapolate2(perm, xsb + 1, ysb + 0, dx1, dy1)
[0m            [1m^[0m[0m
[0m
################
################
In Pycraft. Error: None @ 2023-11-2 15:39:26.621628
Traceback (most recent call last):
  File "D:\Documents\GitHub\PycraftReimagined\src\programs\game_engine.py", line 282, in render_game_engine
    self.matrix, self.position = camera_utils.compute_camera.get_camera_values(
  File "D:\Documents\GitHub\PycraftReimagined\src\programs\utility\camera_utils.py", line 44, in get_camera_values
    cam_matrix = math_utils.gl_look_at(
TypeError: unhashable type: 'Vector3'
################
################
In Pycraft. Error: None @ 2023-11-2 15:40:8.544526
Traceback (most recent call last):
  File "D:\Documents\GitHub\PycraftReimagined\src\programs\game_engine.py", line 245, in render_game_engine
    self.cloud_offset[0] += math_utils.generate_perlin_noise(
TypeError: unhashable type: 'numpy.ndarray'
################
################
In Pycraft. Error: None @ 2023-11-2 15:41:1.3261
Traceback (most recent call last):
  File "D:\Documents\GitHub\PycraftReimagined\src\programs\game_engine.py", line 282, in render_game_engine
    self.matrix, self.position = camera_utils.compute_camera.get_camera_values(
  File "D:\Documents\GitHub\PycraftReimagined\src\programs\utility\camera_utils.py", line 44, in get_camera_values
    cam_matrix = math_utils.gl_look_at(
  File "D:\Documents\GitHub\PycraftReimagined\src\programs\utility\math_utils.py", line 190, in gl_look_at
    x, y, z = compute_position(
  File "C:\Users\pamj0\AppData\Local\Programs\Python\Python310\lib\site-packages\numba\core\dispatcher.py", line 468, in _compile_for_args
    error_rewrite(e, 'typing')
  File "C:\Users\pamj0\AppData\Local\Programs\Python\Python310\lib\site-packages\numba\core\dispatcher.py", line 409, in error_rewrite
    raise e.with_traceback(None)
numba.core.errors.TypingError: Failed in nopython mode pipeline (step: nopython frontend)
[1mUntyped global name 'lru_cache':[0m [1m[1mCannot determine Numba type of <class 'function'>[0m
[1m
File "src\programs\utility\math_utils.py", line 213:[0m
[1m    def compute_position(pos, target, up):
[1m        @lru_cache()
[0m        [1m^[0m[0m
[0m
################
################
In Pycraft. Error: None @ 2023-11-2 15:41:38.755598
Traceback (most recent call last):
  File "D:\Documents\GitHub\PycraftReimagined\src\programs\game_engine.py", line 341, in render_game_engine
    shadow_mapping_utils.shadowmapping_mathematics.compute_shadows(
  File "D:\Documents\GitHub\PycraftReimagined\src\programs\utility\shadow_mapping_utils.py", line 92, in compute_shadows
    sun_light_look_at = math_utils.look_at(
TypeError: unhashable type: 'numpy.ndarray'
################
################
In Pycraft. Error: None @ 2023-11-2 15:42:1.703040
Traceback (most recent call last):
  File "D:\Documents\GitHub\PycraftReimagined\src\programs\game_engine.py", line 341, in render_game_engine
    shadow_mapping_utils.shadowmapping_mathematics.compute_shadows(
  File "D:\Documents\GitHub\PycraftReimagined\src\programs\utility\shadow_mapping_utils.py", line 105, in compute_shadows
    mvp_light = math_utils.multiply(
TypeError: unhashable type: 'numpy.ndarray'
################
################
In Pycraft. Error: None @ 2023-11-2 15:44:37.521971
Traceback (most recent call last):
  File "D:\Documents\GitHub\PycraftReimagined\src\programs\game_engine.py", line 286, in render_game_engine
    self.matrix, self.position = camera_utils.compute_camera.get_camera_values(
TypeError: unhashable type: 'numpy.ndarray'
################
################
In Pycraft. Error: None @ 2023-11-30 19:18:27.177409
Traceback (most recent call last):
  File "D:\Documents\GitHub\PycraftReimagined\src\programs\pycraft_main.py", line 72, in __init__
    Registry.main_menu.main()
  File "D:\Documents\GitHub\PycraftReimagined\src\programs\main_menu.py", line 58, in main
    Registry.splash_process.terminate()
AttributeError: 'NoneType' object has no attribute 'terminate'
################
################
In Pycraft. Error: None @ 2023-11-30 19:24:3.843516
Traceback (most recent call last):
  File "D:\Documents\GitHub\PycraftReimagined\src\programs\game_engine.py", line 66, in __init__
    self.sun = geometry.sphere(
  File "C:\Users\pamj0\AppData\Local\Programs\Python\Python310\lib\site-packages\moderngl_window\geometry\sphere.py", line 77, in sphere
    vao.buffer(vbo_vertices, "3f", [attr_names.POSITION])
  File "C:\Users\pamj0\AppData\Local\Programs\Python\Python310\lib\site-packages\moderngl_window\opengl\vao.py", line 254, in buffer
    buffer = self.ctx.buffer(buffer.tobytes())
  File "C:\Users\pamj0\AppData\Local\Programs\Python\Python310\lib\site-packages\moderngl\__init__.py", line 1885, in buffer
    res.mglo, res._size, res._glo = self.mglo.buffer(data, reserve, dynamic)
_moderngl.Error: cannot create buffer
################
################
In Pycraft. Error: None @ 2023-11-30 19:24:3.859579
Traceback (most recent call last):
  File "D:\Documents\GitHub\PycraftReimagined\src\programs\pycraft_main.py", line 77, in __init__
    Registry.main_menu.main()
  File "D:\Documents\GitHub\PycraftReimagined\src\programs\main_menu.py", line 54, in main
    Registry.hud.update(self.draw, 255)
  File "D:\Documents\GitHub\PycraftReimagined\src\programs\utility\hud_utils.py", line 43, in update
    Registry.game_engine.fbo.clear(1.0, 1.0, 0.0)
AttributeError: type object 'Registry' has no attribute 'game_engine'
################
################
In Pycraft. Error: None @ 2023-11-30 19:24:4.52458
Traceback (most recent call last):
  File "D:\Documents\GitHub\PycraftReimagined\src\programs\pycraft_main.py", line 77, in __init__
    Registry.main_menu.main()
  File "D:\Documents\GitHub\PycraftReimagined\src\programs\main_menu.py", line 54, in main
    Registry.hud.update(self.draw, 255)
  File "D:\Documents\GitHub\PycraftReimagined\src\programs\utility\hud_utils.py", line 43, in update
    Registry.game_engine.fbo.clear(1.0, 1.0, 0.0)
AttributeError: type object 'Registry' has no attribute 'game_engine'

During handling of the above exception, another exception occurred:

Traceback (most recent call last):
  File "D:\Documents\GitHub\PycraftReimagined\src\programs\pycraft_main.py", line 85, in init
    Startup()
  File "D:\Documents\GitHub\PycraftReimagined\src\programs\pycraft_main.py", line 81, in __init__
    error_utils.Error(error=error)
  File "D:\Documents\GitHub\PycraftReimagined\src\programs\utility\error_utils.py", line 64, in __init__
    messagebox.showerror(
  File "C:\Users\pamj0\AppData\Local\Programs\Python\Python310\lib\tkinter\messagebox.py", line 98, in showerror
    return _show(title, message, ERROR, OK, **options)
  File "C:\Users\pamj0\AppData\Local\Programs\Python\Python310\lib\tkinter\messagebox.py", line 76, in _show
    res = Message(**options).show()
  File "C:\Users\pamj0\AppData\Local\Programs\Python\Python310\lib\tkinter\commondialog.py", line 42, in show
    master = _get_temp_root()
  File "C:\Users\pamj0\AppData\Local\Programs\Python\Python310\lib\tkinter\__init__.py", line 306, in _get_temp_root
    raise RuntimeError("No master specified and tkinter is "
RuntimeError: No master specified and tkinter is configured to not support default root
################
################
In Pycraft. Error: None @ 2023-11-30 19:31:15.434918
Traceback (most recent call last):
  File "D:\Documents\GitHub\PycraftReimagined\src\programs\pycraft_main.py", line 72, in __init__
    Registry.hud.update(self.draw, 255)
AttributeError: 'Startup' object has no attribute 'draw'
################
################
In Pycraft. Error: None @ 2023-11-30 19:31:51.795187
Traceback (most recent call last):
  File "D:\Documents\GitHub\PycraftReimagined\src\programs\pycraft_main.py", line 72, in __init__
    Registry.hud.update(Registry.menu_resources.draw, 255)
  File "D:\Documents\GitHub\PycraftReimagined\src\programs\utility\hud_utils.py", line 44, in update
    Registry.game_engine.fbo.clear(1.0, 1.0, 0.0)
AttributeError: type object 'Registry' has no attribute 'game_engine'
################
################
In Pycraft. Error: None @ 2023-11-30 19:35:59.362205
Traceback (most recent call last):
  File "D:\Documents\GitHub\PycraftReimagined\src\programs\utility\file_utils.py", line 100, in create_config
    pickle.dump(
TypeError: cannot pickle 'pygame.surface.Surface' object
################
################
In Pycraft. Error: None @ 2023-12-1 18:17:36.314895
Traceback (most recent call last):
  File "D:\Documents\GitHub\PycraftReimagined\src\programs\pycraft_main.py", line 74, in __init__
    Registry.hud.update(Registry.loading_menu.draw, 255, render_game_engine=False)
  File "D:\Documents\GitHub\PycraftReimagined\src\programs\utility\hud_utils.py", line 69, in update
    self.update_helper(render)
  File "D:\Documents\GitHub\PycraftReimagined\src\programs\utility\hud_utils.py", line 38, in update_helper
    render()
  File "D:\Documents\GitHub\PycraftReimagined\src\programs\utility\menu_utils.py", line 40, in draw
    self.logo,
AttributeError: 'LoadingMenu' object has no attribute 'logo'
################
################
In Pycraft. Error: None @ 2023-12-1 18:18:10.503089
Traceback (most recent call last):
  File "D:\Documents\GitHub\PycraftReimagined\src\programs\pycraft_main.py", line 74, in __init__
    Registry.hud.update(Registry.loading_menu.draw, 255, render_game_engine=False)
  File "D:\Documents\GitHub\PycraftReimagined\src\programs\utility\hud_utils.py", line 69, in update
    self.update_helper(render)
  File "D:\Documents\GitHub\PycraftReimagined\src\programs\utility\hud_utils.py", line 38, in update_helper
    render()
  File "D:\Documents\GitHub\PycraftReimagined\src\programs\utility\menu_utils.py", line 41, in draw
    ((Registry.display_size[0]-self.logo.get_width())/2,
AttributeError: 'LoadingMenu' object has no attribute 'logo'
################
################
In Pycraft. Error: None @ 2023-12-1 18:23:13.418348
Traceback (most recent call last):
  File "D:\Documents\GitHub\PycraftReimagined\src\programs\pycraft_main.py", line 71, in __init__
    Registry.loading_menu = menu_utils.LoadingMenu()
  File "D:\Documents\GitHub\PycraftReimagined\src\programs\utility\menu_utils.py", line 38, in __init__
    self.rendered_splash
AttributeError: 'LoadingMenu' object has no attribute 'rendered_splash'
################
################
In Pycraft. Error: None @ 2023-12-1 18:25:37.763275
Traceback (most recent call last):
  File "D:\Documents\GitHub\PycraftReimagined\src\programs\pycraft_main.py", line 74, in __init__
    Registry.hud.update(Registry.loading_menu.draw, 255, render_game_engine=False)
  File "D:\Documents\GitHub\PycraftReimagined\src\programs\utility\hud_utils.py", line 69, in update
    self.update_helper(render)
  File "D:\Documents\GitHub\PycraftReimagined\src\programs\utility\hud_utils.py", line 38, in update_helper
    render()
  File "D:\Documents\GitHub\PycraftReimagined\src\programs\utility\menu_utils.py", line 50, in draw
    text_utils.MONTSERRAT,
AttributeError: module 'text_utils' has no attribute 'MONTSERRAT'
################
################
In Pycraft. Error: None @ 2023-12-1 18:29:32.401009
Traceback (most recent call last):
  File "D:\Documents\GitHub\PycraftReimagined\src\programs\pycraft_main.py", line 74, in __init__
    Registry.hud.update(Registry.loading_menu.draw, 255, render_game_engine=False)
  File "D:\Documents\GitHub\PycraftReimagined\src\programs\utility\hud_utils.py", line 69, in update
    self.update_helper(render)
  File "D:\Documents\GitHub\PycraftReimagined\src\programs\utility\hud_utils.py", line 38, in update_helper
    render()
  File "D:\Documents\GitHub\PycraftReimagined\src\programs\utility\menu_utils.py", line 50, in draw
    position=[self.total_sidebar_width, self.content_y_position],
AttributeError: 'LoadingMenu' object has no attribute 'total_sidebar_width'
################
################
In Pycraft. Error: None @ 2023-12-1 18:30:56.596027
Traceback (most recent call last):
  File "D:\Documents\GitHub\PycraftReimagined\src\programs\pycraft_main.py", line 74, in __init__
    Registry.hud.update(Registry.loading_menu.draw, 255, render_game_engine=False)
  File "D:\Documents\GitHub\PycraftReimagined\src\programs\utility\hud_utils.py", line 69, in update
    self.update_helper(render)
  File "D:\Documents\GitHub\PycraftReimagined\src\programs\utility\hud_utils.py", line 38, in update_helper
    render()
  File "D:\Documents\GitHub\PycraftReimagined\src\programs\utility\menu_utils.py", line 51, in draw
    Registry.fonts.render_text(
TypeError: TextRenderer.render_text() got an unexpected keyword argument 'cache'
################
################
In Pycraft. Error: None @ 2023-12-1 18:36:15.792124
Traceback (most recent call last):
  File "D:\Documents\GitHub\PycraftReimagined\src\programs\pycraft_main.py", line 74, in __init__
    Registry.hud.update(Registry.loading_menu.draw, 255, render_game_engine=False)
  File "D:\Documents\GitHub\PycraftReimagined\src\programs\utility\hud_utils.py", line 69, in update
    self.update_helper(render)
  File "D:\Documents\GitHub\PycraftReimagined\src\programs\utility\hud_utils.py", line 38, in update_helper
    render()
  File "D:\Documents\GitHub\PycraftReimagined\src\programs\utility\menu_utils.py", line 51, in draw
    Registry.fonts.render_text(
  File "D:\Documents\GitHub\PycraftReimagined\src\programs\utility\text_utils.py", line 136, in render_text
    font = self.text_initiator(size)
  File "D:\Documents\GitHub\PycraftReimagined\src\programs\utility\text_utils.py", line 113, in text_initiator
    self.fonts[str(size)] = pygame.font.Font(self.font_path)
FileNotFoundError: No such file or directory: 'D:\Documents\GitHub\PycraftReimagined\pycraft\fonts\Noto_Sherrif\NotoSerif-VariableFont_wdth,wght.ttf'.
################
################
In Pycraft. Error: None @ 2023-12-1 18:36:35.79086
Traceback (most recent call last):
  File "D:\Documents\GitHub\PycraftReimagined\src\programs\pycraft_main.py", line 74, in __init__
    Registry.hud.update(Registry.loading_menu.draw, 255, render_game_engine=False)
  File "D:\Documents\GitHub\PycraftReimagined\src\programs\utility\hud_utils.py", line 69, in update
    self.update_helper(render)
  File "D:\Documents\GitHub\PycraftReimagined\src\programs\utility\hud_utils.py", line 38, in update_helper
    render()
  File "D:\Documents\GitHub\PycraftReimagined\src\programs\utility\menu_utils.py", line 51, in draw
    Registry.fonts.render_text(
  File "D:\Documents\GitHub\PycraftReimagined\src\programs\utility\text_utils.py", line 136, in render_text
    font = self.text_initiator(size)
  File "D:\Documents\GitHub\PycraftReimagined\src\programs\utility\text_utils.py", line 113, in text_initiator
    self.fonts[str(size)] = pygame.font.Font(self.font_path)
FileNotFoundError: No such file or directory: 'D:\Documents\GitHub\PycraftReimagined\pycraft\fonts\Noto_Sherrif\NotoSerif-VariableFont_wdth,wght.ttf'.
################
################
In Pycraft. Error: None @ 2023-12-1 18:36:57.685985
Traceback (most recent call last):
  File "D:\Documents\GitHub\PycraftReimagined\src\programs\pycraft_main.py", line 74, in __init__
    Registry.hud.update(Registry.loading_menu.draw, 255, render_game_engine=False)
  File "D:\Documents\GitHub\PycraftReimagined\src\programs\utility\hud_utils.py", line 69, in update
    self.update_helper(render)
  File "D:\Documents\GitHub\PycraftReimagined\src\programs\utility\hud_utils.py", line 38, in update_helper
    render()
  File "D:\Documents\GitHub\PycraftReimagined\src\programs\utility\menu_utils.py", line 51, in draw
    Registry.fonts.render_text(
  File "D:\Documents\GitHub\PycraftReimagined\src\programs\utility\text_utils.py", line 136, in render_text
    font = self.text_initiator(size)
  File "D:\Documents\GitHub\PycraftReimagined\src\programs\utility\text_utils.py", line 113, in text_initiator
    self.fonts[str(size)] = pygame.font.Font(self.font_path)
FileNotFoundError: No such file or directory: 'D:\Documents\GitHub\PycraftReimagined\src\fonts\Noto_Sherrif\NotoSerif-VariableFont_wdth,wght.ttf'.
################
################
In Pycraft. Error: None @ 2023-12-1 20:34:7.929432
Traceback (most recent call last):
  File "D:\Documents\GitHub\PycraftReimagined\src\programs\pycraft_main.py", line 74, in __init__
    Registry.hud.update(Registry.loading_menu.draw, 255, render_game_engine=False)
  File "D:\Documents\GitHub\PycraftReimagined\src\programs\utility\hud_utils.py", line 69, in update
    self.update_helper(render)
  File "D:\Documents\GitHub\PycraftReimagined\src\programs\utility\hud_utils.py", line 38, in update_helper
    render()
  File "D:\Documents\GitHub\PycraftReimagined\src\programs\utility\menu_utils.py", line 55, in draw
    Registry.fonts.render_text(
  File "D:\Documents\GitHub\PycraftReimagined\src\programs\utility\text_utils.py", line 136, in render_text
    font = self.text_initiator(size)
  File "D:\Documents\GitHub\PycraftReimagined\src\programs\utility\text_utils.py", line 107, in text_initiator
    if font == str(size):
UnboundLocalError: local variable 'font' referenced before assignment
################
################
In Pycraft. Error: None @ 2023-12-1 20:37:9.228364
Traceback (most recent call last):
  File "D:\Documents\GitHub\PycraftReimagined\src\programs\utility\file_utils.py", line 102, in create_config
    pickle.dump(
TypeError: cannot pickle 'pygame.surface.Surface' object
################
################
In Pycraft. Error: None @ 2023-12-1 20:40:28.659576
Traceback (most recent call last):
  File "D:\Documents\GitHub\PycraftReimagined\src\programs\utility\file_utils.py", line 104, in create_config
    pickle.dump(
TypeError: cannot pickle 'pygame.surface.Surface' object
################
################
In Pycraft. Error: None @ 2023-12-1 20:51:25.492009
Traceback (most recent call last):
  File "D:\Documents\GitHub\PycraftReimagined\src\programs\pycraft_main.py", line 74, in __init__
    Registry.menu_resources.main()
AttributeError: 'MenuResources' object has no attribute 'main'
################
################
In Pycraft. Error: None @ 2023-12-1 20:58:6.246293
Traceback (most recent call last):
  File "D:\Documents\GitHub\PycraftReimagined\src\programs\pycraft_main.py", line 74, in __init__
    Registry.hud.update(self.draw, 255, render_game_engine=False)
AttributeError: 'Startup' object has no attribute 'draw'
################
################
In Pycraft. Error: None @ 2023-12-1 21:0:58.883489
Traceback (most recent call last):
  File "D:\Documents\GitHub\PycraftReimagined\src\programs\pycraft_main.py", line 72, in __init__
    Registry.loading_menu = loading_menu.Loading()
AttributeError: module 'loading_menu' has no attribute 'Loading'
################
################
In Pycraft. Error: None @ 2023-12-1 21:3:8.106571
Traceback (most recent call last):
  File "D:\Documents\GitHub\PycraftReimagined\src\programs\pycraft_main.py", line 73, in __init__
    Registry.loading_menu.main()
  File "D:\Documents\GitHub\PycraftReimagined\src\programs\loading_menu.py", line 71, in main
    Registry.hud.update(self.draw, 255)
AttributeError: type object 'Registry' has no attribute 'hud'
################
################
In Pycraft. Error: None @ 2023-12-1 21:15:35.892690
Traceback (most recent call last):
  File "D:\Documents\GitHub\PycraftReimagined\src\programs\pycraft_main.py", line 79, in __init__
    Registry.main_menu.main()
  File "D:\Documents\GitHub\PycraftReimagined\src\programs\main_menu.py", line 49, in main
    (_, run) = Registry.events.handle()
  File "D:\Documents\GitHub\PycraftReimagined\src\programs\utility\event_utils.py", line 39, in handle
    Registry.display_size = self.display.get_size()
AttributeError: 'EventsManager' object has no attribute 'display'
################
################
In Pycraft. Error: None @ 2023-12-1 21:25:34.204134
Traceback (most recent call last):
  File "D:\Documents\GitHub\PycraftReimagined\src\programs\game_engine.py", line 66, in __init__
    self.sun = geometry.sphere(
  File "C:\Users\pamj0\AppData\Local\Programs\Python\Python310\lib\site-packages\moderngl_window\geometry\sphere.py", line 77, in sphere
    vao.buffer(vbo_vertices, "3f", [attr_names.POSITION])
  File "C:\Users\pamj0\AppData\Local\Programs\Python\Python310\lib\site-packages\moderngl_window\opengl\vao.py", line 254, in buffer
    buffer = self.ctx.buffer(buffer.tobytes())
  File "C:\Users\pamj0\AppData\Local\Programs\Python\Python310\lib\site-packages\moderngl\__init__.py", line 1885, in buffer
    res.mglo, res._size, res._glo = self.mglo.buffer(data, reserve, dynamic)
_moderngl.Error: cannot create buffer
################
################
In Pycraft. Error: None @ 2023-12-2 11:20:31.744732
Traceback (most recent call last):
  File "D:\Documents\GitHub\PycraftReimagined\src\programs\game_engine.py", line 235, in __init__
    image = Image.open(io.BytesIO(self.texture2.read()))
  File "C:\Users\pamj0\AppData\Local\Programs\Python\Python310\lib\site-packages\PIL\Image.py", line 3298, in open
    raise UnidentifiedImageError(msg)
PIL.UnidentifiedImageError: cannot identify image file <_io.BytesIO object at 0x000001D15F7D38D0>
################
################
In Pycraft. Error: None @ 2023-12-2 11:22:23.168934
Traceback (most recent call last):
  File "D:\Documents\GitHub\PycraftReimagined\src\programs\pycraft_main.py", line 75, in __init__
    Registry.hud.update(Registry.loading_menu.draw, 255, render_game_engine=False)
  File "D:\Documents\GitHub\PycraftReimagined\src\programs\utility\hud_utils.py", line 78, in update
    image = Image.frombytes('RGBA', (1280,720), Registry.game_engine.texture2.read(), 'raw')
AttributeError: type object 'Registry' has no attribute 'game_engine'
################
################
In Pycraft. Error: None @ 2023-12-2 11:23:29.460037
Traceback (most recent call last):
  File "D:\Documents\GitHub\PycraftReimagined\src\programs\pycraft_main.py", line 80, in __init__
    Registry.main_menu.main()
  File "D:\Documents\GitHub\PycraftReimagined\src\programs\main_menu.py", line 50, in main
    Registry.hud.update(self.draw, 255)
  File "D:\Documents\GitHub\PycraftReimagined\src\programs\utility\hud_utils.py", line 79, in update
    image = Image.frombytes('BGRA', (1280,720), Registry.game_engine.texture2.read(), 'raw')
  File "C:\Users\pamj0\AppData\Local\Programs\Python\Python310\lib\site-packages\PIL\Image.py", line 2969, in frombytes
    im = new(mode, size)
  File "C:\Users\pamj0\AppData\Local\Programs\Python\Python310\lib\site-packages\PIL\Image.py", line 2933, in new
    return im._new(core.fill(mode, size, color))
ValueError: unrecognized image mode
################
################
In Pycraft. Error: None @ 2023-12-2 11:24:45.909506
Traceback (most recent call last):
  File "D:\Documents\GitHub\PycraftReimagined\src\programs\pycraft_main.py", line 80, in __init__
    Registry.main_menu.main()
  File "D:\Documents\GitHub\PycraftReimagined\src\programs\main_menu.py", line 50, in main
    Registry.hud.update(self.draw, 255)
  File "D:\Documents\GitHub\PycraftReimagined\src\programs\utility\hud_utils.py", line 79, in update
    image = Image.frombytes('BGR', (1280,720), Registry.game_engine.texture2.read(), 'raw')
  File "C:\Users\pamj0\AppData\Local\Programs\Python\Python310\lib\site-packages\PIL\Image.py", line 2969, in frombytes
    im = new(mode, size)
  File "C:\Users\pamj0\AppData\Local\Programs\Python\Python310\lib\site-packages\PIL\Image.py", line 2933, in new
    return im._new(core.fill(mode, size, color))
ValueError: unrecognized image mode
################
################
In Pycraft. Error: None @ 2023-12-2 11:25:43.812558
Traceback (most recent call last):
  File "D:\Documents\GitHub\PycraftReimagined\src\programs\pycraft_main.py", line 80, in __init__
    Registry.main_menu.main()
  File "D:\Documents\GitHub\PycraftReimagined\src\programs\main_menu.py", line 50, in main
    Registry.hud.update(self.draw, 255)
  File "D:\Documents\GitHub\PycraftReimagined\src\programs\utility\hud_utils.py", line 79, in update
    image = Image.frombytes('BGR;16', (1280,720), Registry.game_engine.texture2.read(), 'raw')
  File "C:\Users\pamj0\AppData\Local\Programs\Python\Python310\lib\site-packages\PIL\Image.py", line 2970, in frombytes
    im.frombytes(data, decoder_name, args)
  File "C:\Users\pamj0\AppData\Local\Programs\Python\Python310\lib\site-packages\PIL\Image.py", line 820, in frombytes
    d = _getdecoder(self.mode, decoder_name, args)
  File "C:\Users\pamj0\AppData\Local\Programs\Python\Python310\lib\site-packages\PIL\Image.py", line 414, in _getdecoder
    return decoder(mode, *args + extra)
ValueError: unknown raw mode for given image mode
################
################
In Pycraft. Error: None @ 2023-12-2 11:30:8.270094
Traceback (most recent call last):
  File "D:\Documents\GitHub\PycraftReimagined\src\programs\pycraft_main.py", line 80, in __init__
    Registry.main_menu.main()
  File "D:\Documents\GitHub\PycraftReimagined\src\programs\main_menu.py", line 50, in main
    Registry.hud.update(self.draw, 255)
  File "D:\Documents\GitHub\PycraftReimagined\src\programs\utility\hud_utils.py", line 80, in update
    image = image[::-1]
TypeError: 'Image' object is not subscriptable
################
################
In Pycraft. Error: None @ 2023-12-2 11:30:33.260149
Traceback (most recent call last):
  File "D:\Documents\GitHub\PycraftReimagined\src\programs\pycraft_main.py", line 80, in __init__
    Registry.main_menu.main()
  File "D:\Documents\GitHub\PycraftReimagined\src\programs\main_menu.py", line 50, in main
    Registry.hud.update(self.draw, 255)
  File "D:\Documents\GitHub\PycraftReimagined\src\programs\utility\hud_utils.py", line 80, in update
    image = image[:, :, ::-1]
TypeError: 'Image' object is not subscriptable
################
################
In Pycraft. Error: None @ 2023-12-2 11:31:21.453954
Traceback (most recent call last):
  File "D:\Documents\GitHub\PycraftReimagined\src\programs\pycraft_main.py", line 80, in __init__
    Registry.main_menu.main()
  File "D:\Documents\GitHub\PycraftReimagined\src\programs\main_menu.py", line 50, in main
    Registry.hud.update(self.draw, 255)
  File "D:\Documents\GitHub\PycraftReimagined\src\programs\utility\hud_utils.py", line 80, in update
    image = image = image[...,::-1]
TypeError: 'Image' object is not subscriptable
################
################
In Pycraft. Error: None @ 2023-12-2 11:31:40.759814
Traceback (most recent call last):
  File "D:\Documents\GitHub\PycraftReimagined\src\programs\pycraft_main.py", line 80, in __init__
    Registry.main_menu.main()
  File "D:\Documents\GitHub\PycraftReimagined\src\programs\main_menu.py", line 50, in main
    Registry.hud.update(self.draw, 255)
  File "D:\Documents\GitHub\PycraftReimagined\src\programs\utility\hud_utils.py", line 79, in update
    image = Image.frombytes('RGBA', (1280,720), Registry.game_engine.texture2.read()[...,::-1], 'raw')
TypeError: byte indices must be integers or slices, not tuple
################
################
In Pycraft. Error: None @ 2023-12-2 11:32:45.657049
Traceback (most recent call last):
  File "D:\Documents\GitHub\PycraftReimagined\src\programs\pycraft_main.py", line 80, in __init__
    Registry.main_menu.main()
  File "D:\Documents\GitHub\PycraftReimagined\src\programs\main_menu.py", line 50, in main
    Registry.hud.update(self.draw, 255)
  File "D:\Documents\GitHub\PycraftReimagined\src\programs\utility\hud_utils.py", line 86, in update
    sub = Image.open(Registry.game_engine.texture2.read())
  File "C:\Users\pamj0\AppData\Local\Programs\Python\Python310\lib\site-packages\PIL\Image.py", line 3236, in open
    fp = builtins.open(filename, "rb")
UnicodeDecodeError: 'utf-8' codec can't decode byte 0xb5 in position 0: invalid start byte
################
################
In Pycraft. Error: None @ 2023-12-2 11:55:28.605937
Traceback (most recent call last):
  File "D:\Documents\GitHub\PycraftReimagined\src\programs\pycraft_main.py", line 75, in __init__
    Registry.hud.update(Registry.loading_menu.draw, 255, render_game_engine=False, background=self.text2)
AttributeError: 'Startup' object has no attribute 'text2'
################
################
In Pycraft. Error: None @ 2023-12-2 11:55:52.403631
Traceback (most recent call last):
  File "D:\Documents\GitHub\PycraftReimagined\src\programs\pycraft_main.py", line 75, in __init__
    Registry.hud.update(Registry.loading_menu.draw, 255, render_game_engine=False, background=Registry.loading_menu.text2)
AttributeError: 'LoadingMenu' object has no attribute 'text2'
################
################
In Pycraft. Error: None @ 2023-12-2 12:0:2.184781
Traceback (most recent call last):
  File "D:\Documents\GitHub\PycraftReimagined\src\programs\pycraft_main.py", line 70, in __init__
    Registry.loading_menu = loading_menu.LoadingMenu()
  File "D:\Documents\GitHub\PycraftReimagined\src\programs\loading_menu.py", line 42, in __init__
    self.background_image = pygame.image.load(image_path)
FileNotFoundError: No such file or directory: 'D:\Documents\GitHub\PycraftReimagined\temporary\last_scene.png'.
################
################
In Pycraft. Error: None @ 2023-12-2 12:2:53.845271
Traceback (most recent call last):
  File "D:\Documents\GitHub\PycraftReimagined\src\programs\pycraft_main.py", line 70, in __init__
    Registry.loading_menu = loading_menu.LoadingMenu()
  File "D:\Documents\GitHub\PycraftReimagined\src\programs\loading_menu.py", line 42, in __init__
    self.background_image = pygame.image.load(image_path)
FileNotFoundError: No such file or directory: 'D:\Documents\GitHub\PycraftReimagined\temporary\last_scene.png'.
################
################
In Pycraft. Error: None @ 2023-12-3 10:41:13.124811
Traceback (most recent call last):
  File "D:\Documents\GitHub\PycraftReimagined\src\programs\pycraft_main.py", line 69, in __init__
    Registry.menu_resources = menu_utils.MenuResources()
  File "D:\Documents\GitHub\PycraftReimagined\src\programs\utility\menu_utils.py", line 28, in __init__
    self.logo = image_utils.Icon().pycraft_icon(self.logo_path)
  File "D:\Documents\GitHub\PycraftReimagined\src\programs\utility\image_utils.py", line 84, in pycraft_icon
    image = image.resize((new_width, new_height))
  File "C:\Users\pamj0\AppData\Local\Programs\Python\Python310\lib\site-packages\PIL\Image.py", line 2171, in resize
    im = im.resize(size, resample, box)
  File "C:\Users\pamj0\AppData\Local\Programs\Python\Python310\lib\site-packages\PIL\Image.py", line 2193, in resize
    return self._new(self.im.resize(size, resample, box))
TypeError: 'float' object cannot be interpreted as an integer
################
################
In Pycraft. Error: None @ 2023-12-3 11:32:9.919841
Traceback (most recent call last):
  File "D:\Documents\GitHub\PycraftReimagined\src\programs\pycraft_main.py", line 74, in __init__
    Registry.hud.update(Registry.loading_menu.draw, 255, render_game_engine=False, background=Registry.loading_menu.tex2)
  File "D:\Documents\GitHub\PycraftReimagined\src\programs\utility\hud_utils.py", line 76, in update
    self.update_helper(render)
  File "D:\Documents\GitHub\PycraftReimagined\src\programs\utility\hud_utils.py", line 38, in update_helper
    render()
  File "D:\Documents\GitHub\PycraftReimagined\src\programs\loading_menu.py", line 56, in draw
    content_y_position = (Registry.display_size[1]-self.logo.get_height())/2
AttributeError: 'LoadingMenu' object has no attribute 'logo'
################
################
In Pycraft. Error: None @ 2023-12-3 11:32:26.373950
Traceback (most recent call last):
  File "D:\Documents\GitHub\PycraftReimagined\src\programs\pycraft_main.py", line 74, in __init__
    Registry.hud.update(Registry.loading_menu.draw, 255, render_game_engine=False, background=Registry.loading_menu.tex2)
  File "D:\Documents\GitHub\PycraftReimagined\src\programs\utility\hud_utils.py", line 76, in update
    self.update_helper(render)
  File "D:\Documents\GitHub\PycraftReimagined\src\programs\utility\hud_utils.py", line 38, in update_helper
    render()
  File "D:\Documents\GitHub\PycraftReimagined\src\programs\loading_menu.py", line 60, in draw
    ((Registry.display_size[0]-self.logo.get_width())/2,
AttributeError: 'LoadingMenu' object has no attribute 'logo'
################
################
In Pycraft. Error: None @ 2023-12-3 11:33:9.600430
Traceback (most recent call last):
  File "D:\Documents\GitHub\PycraftReimagined\src\programs\pycraft_main.py", line 74, in __init__
    Registry.hud.update(Registry.loading_menu.draw, 255, render_game_engine=False, background=Registry.loading_menu.tex2)
  File "D:\Documents\GitHub\PycraftReimagined\src\programs\utility\hud_utils.py", line 76, in update
    self.update_helper(render)
  File "D:\Documents\GitHub\PycraftReimagined\src\programs\utility\hud_utils.py", line 38, in update_helper
    render()
  File "D:\Documents\GitHub\PycraftReimagined\src\programs\loading_menu.py", line 60, in draw
    ((Registry.display_size[0]-Registry.menu_resources.logo.logo.get_width())/2,
AttributeError: 'pygame.surface.Surface' object has no attribute 'logo'
################
################
In Pycraft. Error: None @ 2023-12-3 11:40:14.961762
Traceback (most recent call last):
  File "D:\Documents\GitHub\PycraftReimagined\src\programs\pycraft_main.py", line 79, in __init__
    Registry.main_menu.main()
  File "D:\Documents\GitHub\PycraftReimagined\src\programs\main_menu.py", line 50, in main
    Registry.hud.update(self.draw, 255)
  File "D:\Documents\GitHub\PycraftReimagined\src\programs\utility\hud_utils.py", line 76, in update
    self.update_helper(render)
  File "D:\Documents\GitHub\PycraftReimagined\src\programs\utility\hud_utils.py", line 38, in update_helper
    render()
  File "D:\Documents\GitHub\PycraftReimagined\src\programs\main_menu.py", line 35, in draw
    ((Registry.display_size[0]-self.logo.get_width())/2, (Registry.display_size[1]-self.logo.get_height())/2))
AttributeError: 'Home' object has no attribute 'logo'
################